Using TensorFlow backend.
/global/scratch/projects/fc_mvslab/conda/adpred/lib/python3.7/site-packages/tensorflow/python/framework/dtypes.py:516: FutureWarning: Passing (type, 1) or '1type' as a synonym of type is deprecated; in a future version of numpy, it will be understood as (type, (1,)) / '(1,)type'.
  _np_qint8 = np.dtype([("qint8", np.int8, 1)])
/global/scratch/projects/fc_mvslab/conda/adpred/lib/python3.7/site-packages/tensorflow/python/framework/dtypes.py:517: FutureWarning: Passing (type, 1) or '1type' as a synonym of type is deprecated; in a future version of numpy, it will be understood as (type, (1,)) / '(1,)type'.
  _np_quint8 = np.dtype([("quint8", np.uint8, 1)])
/global/scratch/projects/fc_mvslab/conda/adpred/lib/python3.7/site-packages/tensorflow/python/framework/dtypes.py:518: FutureWarning: Passing (type, 1) or '1type' as a synonym of type is deprecated; in a future version of numpy, it will be understood as (type, (1,)) / '(1,)type'.
  _np_qint16 = np.dtype([("qint16", np.int16, 1)])
/global/scratch/projects/fc_mvslab/conda/adpred/lib/python3.7/site-packages/tensorflow/python/framework/dtypes.py:519: FutureWarning: Passing (type, 1) or '1type' as a synonym of type is deprecated; in a future version of numpy, it will be understood as (type, (1,)) / '(1,)type'.
  _np_quint16 = np.dtype([("quint16", np.uint16, 1)])
/global/scratch/projects/fc_mvslab/conda/adpred/lib/python3.7/site-packages/tensorflow/python/framework/dtypes.py:520: FutureWarning: Passing (type, 1) or '1type' as a synonym of type is deprecated; in a future version of numpy, it will be understood as (type, (1,)) / '(1,)type'.
  _np_qint32 = np.dtype([("qint32", np.int32, 1)])
/global/scratch/projects/fc_mvslab/conda/adpred/lib/python3.7/site-packages/tensorflow/python/framework/dtypes.py:525: FutureWarning: Passing (type, 1) or '1type' as a synonym of type is deprecated; in a future version of numpy, it will be understood as (type, (1,)) / '(1,)type'.
  np_resource = np.dtype([("resource", np.ubyte, 1)])
/global/scratch/projects/fc_mvslab/conda/adpred/lib/python3.7/site-packages/tensorboard/compat/tensorflow_stub/dtypes.py:541: FutureWarning: Passing (type, 1) or '1type' as a synonym of type is deprecated; in a future version of numpy, it will be understood as (type, (1,)) / '(1,)type'.
  _np_qint8 = np.dtype([("qint8", np.int8, 1)])
/global/scratch/projects/fc_mvslab/conda/adpred/lib/python3.7/site-packages/tensorboard/compat/tensorflow_stub/dtypes.py:542: FutureWarning: Passing (type, 1) or '1type' as a synonym of type is deprecated; in a future version of numpy, it will be understood as (type, (1,)) / '(1,)type'.
  _np_quint8 = np.dtype([("quint8", np.uint8, 1)])
/global/scratch/projects/fc_mvslab/conda/adpred/lib/python3.7/site-packages/tensorboard/compat/tensorflow_stub/dtypes.py:543: FutureWarning: Passing (type, 1) or '1type' as a synonym of type is deprecated; in a future version of numpy, it will be understood as (type, (1,)) / '(1,)type'.
  _np_qint16 = np.dtype([("qint16", np.int16, 1)])
/global/scratch/projects/fc_mvslab/conda/adpred/lib/python3.7/site-packages/tensorboard/compat/tensorflow_stub/dtypes.py:544: FutureWarning: Passing (type, 1) or '1type' as a synonym of type is deprecated; in a future version of numpy, it will be understood as (type, (1,)) / '(1,)type'.
  _np_quint16 = np.dtype([("quint16", np.uint16, 1)])
/global/scratch/projects/fc_mvslab/conda/adpred/lib/python3.7/site-packages/tensorboard/compat/tensorflow_stub/dtypes.py:545: FutureWarning: Passing (type, 1) or '1type' as a synonym of type is deprecated; in a future version of numpy, it will be understood as (type, (1,)) / '(1,)type'.
  _np_qint32 = np.dtype([("qint32", np.int32, 1)])
/global/scratch/projects/fc_mvslab/conda/adpred/lib/python3.7/site-packages/tensorboard/compat/tensorflow_stub/dtypes.py:550: FutureWarning: Passing (type, 1) or '1type' as a synonym of type is deprecated; in a future version of numpy, it will be understood as (type, (1,)) / '(1,)type'.
  np_resource = np.dtype([("resource", np.ubyte, 1)])

    
If you wish to use a local installation of psipred, please indicate this,
    by assigning the path to local_psipred (e.g. local_psipred = "~/psipred/run_psipred")


WARNING:tensorflow:From /global/scratch/projects/fc_mvslab/conda/adpred/lib/python3.7/site-packages/keras/backend/tensorflow_backend.py:95: The name tf.reset_default_graph is deprecated. Please use tf.compat.v1.reset_default_graph instead.

WARNING:tensorflow:From /global/scratch/projects/fc_mvslab/conda/adpred/lib/python3.7/site-packages/keras/backend/tensorflow_backend.py:98: The name tf.placeholder_with_default is deprecated. Please use tf.compat.v1.placeholder_with_default instead.

WARNING:tensorflow:From /global/scratch/projects/fc_mvslab/conda/adpred/lib/python3.7/site-packages/keras/backend/tensorflow_backend.py:102: The name tf.get_default_graph is deprecated. Please use tf.compat.v1.get_default_graph instead.

WARNING:tensorflow:From /global/scratch/projects/fc_mvslab/conda/adpred/lib/python3.7/site-packages/keras/backend/tensorflow_backend.py:517: The name tf.placeholder is deprecated. Please use tf.compat.v1.placeholder instead.

WARNING:tensorflow:From /global/scratch/projects/fc_mvslab/conda/adpred/lib/python3.7/site-packages/keras/backend/tensorflow_backend.py:4138: The name tf.random_uniform is deprecated. Please use tf.random.uniform instead.

WARNING:tensorflow:From /global/scratch/projects/fc_mvslab/conda/adpred/lib/python3.7/site-packages/keras/backend/tensorflow_backend.py:3445: calling dropout (from tensorflow.python.ops.nn_ops) with keep_prob is deprecated and will be removed in a future version.
Instructions for updating:
Please use `rate` instead of `keep_prob`. Rate should be set to `rate = 1 - keep_prob`.
WARNING:tensorflow:From /global/scratch/projects/fc_mvslab/conda/adpred/lib/python3.7/site-packages/keras/optimizers.py:790: The name tf.train.Optimizer is deprecated. Please use tf.compat.v1.train.Optimizer instead.

WARNING:tensorflow:From /global/scratch/projects/fc_mvslab/conda/adpred/lib/python3.7/site-packages/tensorflow/python/ops/nn_impl.py:180: add_dispatch_support.<locals>.wrapper (from tensorflow.python.ops.array_ops) is deprecated and will be removed in a future version.
Instructions for updating:
Use tf.where in 2.0, which has the same broadcast rule as np.where
WARNING:tensorflow:From /global/scratch/projects/fc_mvslab/conda/adpred/lib/python3.7/site-packages/adpred/lib/utils.py:55: The name tf.metrics.auc is deprecated. Please use tf.compat.v1.metrics.auc instead.

WARNING:tensorflow:From /global/scratch/projects/fc_mvslab/conda/adpred/lib/python3.7/site-packages/tensorflow/python/ops/metrics_impl.py:809: div (from tensorflow.python.ops.math_ops) is deprecated and will be removed in a future version.
Instructions for updating:
Deprecated in favor of operator or tf.math.divide.
2025-05-15 14:42:10.535629: I tensorflow/core/platform/cpu_feature_guard.cc:142] Your CPU supports instructions that this TensorFlow binary was not compiled to use: SSE4.1 SSE4.2 AVX AVX2 FMA
2025-05-15 14:42:11.952601: I tensorflow/core/platform/profile_utils/cpu_utils.cc:94] CPU Frequency: 2300000000 Hz
2025-05-15 14:42:12.033652: I tensorflow/compiler/xla/service/service.cc:168] XLA service 0x55d4b634b9e0 executing computations on platform Host. Devices:
2025-05-15 14:42:12.062967: I tensorflow/compiler/xla/service/service.cc:175]   StreamExecutor device (0): <undefined>, <undefined>
2025-05-15 14:42:14.235128: W tensorflow/compiler/jit/mark_for_compilation_pass.cc:1412] (One-time warning): Not using XLA:CPU for cluster because envvar TF_XLA_FLAGS=--tf_xla_cpu_global_jit was not set.  If you want XLA:CPU, either set that envvar, or use experimental_jit_scope to enable XLA:CPU.  To confirm that XLA is active, pass --vmodule=xla_compilation_cache=1 (as a proper command-line flag, not via TF_XLA_FLAGS) or set the envvar XLA_FLAGS=--xla_hlo_profile.
Traceback (most recent call last):
  File "/global/scratch/projects/fc_mvslab/conda/adpred/lib/python3.7/site-packages/urllib3/connection.py", line 160, in _new_conn
    (self._dns_host, self.port), self.timeout, **extra_kw
  File "/global/scratch/projects/fc_mvslab/conda/adpred/lib/python3.7/site-packages/urllib3/util/connection.py", line 84, in create_connection
    raise err
  File "/global/scratch/projects/fc_mvslab/conda/adpred/lib/python3.7/site-packages/urllib3/util/connection.py", line 74, in create_connection
    sock.connect(sa)
ConnectionRefusedError: [Errno 111] Connection refused

During handling of the above exception, another exception occurred:

Traceback (most recent call last):
  File "/global/scratch/projects/fc_mvslab/conda/adpred/lib/python3.7/site-packages/urllib3/connectionpool.py", line 677, in urlopen
    chunked=chunked,
  File "/global/scratch/projects/fc_mvslab/conda/adpred/lib/python3.7/site-packages/urllib3/connectionpool.py", line 392, in _make_request
    conn.request(method, url, **httplib_request_kw)
  File "/global/scratch/projects/fc_mvslab/conda/adpred/lib/python3.7/http/client.py", line 1281, in request
    self._send_request(method, url, body, headers, encode_chunked)
  File "/global/scratch/projects/fc_mvslab/conda/adpred/lib/python3.7/http/client.py", line 1327, in _send_request
    self.endheaders(body, encode_chunked=encode_chunked)
  File "/global/scratch/projects/fc_mvslab/conda/adpred/lib/python3.7/http/client.py", line 1276, in endheaders
    self._send_output(message_body, encode_chunked=encode_chunked)
  File "/global/scratch/projects/fc_mvslab/conda/adpred/lib/python3.7/http/client.py", line 1036, in _send_output
    self.send(msg)
  File "/global/scratch/projects/fc_mvslab/conda/adpred/lib/python3.7/http/client.py", line 976, in send
    self.connect()
  File "/global/scratch/projects/fc_mvslab/conda/adpred/lib/python3.7/site-packages/urllib3/connection.py", line 187, in connect
    conn = self._new_conn()
  File "/global/scratch/projects/fc_mvslab/conda/adpred/lib/python3.7/site-packages/urllib3/connection.py", line 172, in _new_conn
    self, "Failed to establish a new connection: %s" % e
urllib3.exceptions.NewConnectionError: <urllib3.connection.HTTPConnection object at 0x14eaa017ed50>: Failed to establish a new connection: [Errno 111] Connection refused

During handling of the above exception, another exception occurred:

Traceback (most recent call last):
  File "/global/scratch/projects/fc_mvslab/conda/adpred/lib/python3.7/site-packages/requests/adapters.py", line 449, in send
    timeout=timeout
  File "/global/scratch/projects/fc_mvslab/conda/adpred/lib/python3.7/site-packages/urllib3/connectionpool.py", line 727, in urlopen
    method, url, error=e, _pool=self, _stacktrace=sys.exc_info()[2]
  File "/global/scratch/projects/fc_mvslab/conda/adpred/lib/python3.7/site-packages/urllib3/util/retry.py", line 446, in increment
    raise MaxRetryError(_pool, url, error or ResponseError(cause))
urllib3.exceptions.MaxRetryError: HTTPConnectionPool(host='bioinf.cs.ucl.ac.uk', port=80): Max retries exceeded with url: /psipred/api/submission/f237357e-323f-11f0-ab5d-00163e100466 (Caused by NewConnectionError('<urllib3.connection.HTTPConnection object at 0x14eaa017ed50>: Failed to establish a new connection: [Errno 111] Connection refused'))

During handling of the above exception, another exception occurred:

Traceback (most recent call last):
  File "/global/scratch/projects/fc_mvslab/OpenProjects/Sanjana/adpred_files/use_ADPred.py", line 105, in <module>
  File "/global/scratch/projects/fc_mvslab/conda/adpred/lib/python3.7/site-packages/adpred/ADpred.py", line 269, in predict
    prot.predict_second_struct()
  File "/global/scratch/projects/fc_mvslab/conda/adpred/lib/python3.7/site-packages/adpred/ADpred.py", line 258, in predict_second_struct
    prot.second_struct = calculate_psipred(rand_fasta_name)    
  File "/global/scratch/projects/fc_mvslab/conda/adpred/lib/python3.7/site-packages/adpred/ADpred.py", line 66, in calculate_psipred
    struct = get_psipred(fasta_name)
  File "/global/scratch/projects/fc_mvslab/conda/adpred/lib/python3.7/site-packages/adpred/lib/utils.py", line 182, in get_psipred
    a = requests.get(submission)
  File "/global/scratch/projects/fc_mvslab/conda/adpred/lib/python3.7/site-packages/requests/api.py", line 76, in get
    return request('get', url, params=params, **kwargs)
  File "/global/scratch/projects/fc_mvslab/conda/adpred/lib/python3.7/site-packages/requests/api.py", line 61, in request
    return session.request(method=method, url=url, **kwargs)
  File "/global/scratch/projects/fc_mvslab/conda/adpred/lib/python3.7/site-packages/requests/sessions.py", line 530, in request
    resp = self.send(prep, **send_kwargs)
  File "/global/scratch/projects/fc_mvslab/conda/adpred/lib/python3.7/site-packages/requests/sessions.py", line 643, in send
    r = adapter.send(request, **kwargs)
  File "/global/scratch/projects/fc_mvslab/conda/adpred/lib/python3.7/site-packages/requests/adapters.py", line 516, in send
    raise ConnectionError(e, request=request)
requests.exceptions.ConnectionError: HTTPConnectionPool(host='bioinf.cs.ucl.ac.uk', port=80): Max retries exceeded with url: /psipred/api/submission/f237357e-323f-11f0-ab5d-00163e100466 (Caused by NewConnectionError('<urllib3.connection.HTTPConnection object at 0x14eaa017ed50>: Failed to establish a new connection: [Errno 111] Connection refused'))
